Traceback (most recent call last):
  File "/Users/jvanscho/miniconda3/lib/python3.10/site-packages/jupyter_cache/executors/utils.py", line 51, in single_nb_execution
    executenb(
  File "/Users/jvanscho/miniconda3/lib/python3.10/site-packages/nbclient/client.py", line 1204, in execute
    return NotebookClient(nb=nb, resources=resources, km=km, **kwargs).execute()
  File "/Users/jvanscho/miniconda3/lib/python3.10/site-packages/nbclient/util.py", line 84, in wrapped
    return just_run(coro(*args, **kwargs))
  File "/Users/jvanscho/miniconda3/lib/python3.10/site-packages/nbclient/util.py", line 62, in just_run
    return loop.run_until_complete(coro)
  File "/Users/jvanscho/miniconda3/lib/python3.10/asyncio/base_events.py", line 649, in run_until_complete
    return future.result()
  File "/Users/jvanscho/miniconda3/lib/python3.10/site-packages/nbclient/client.py", line 663, in async_execute
    await self.async_execute_cell(
  File "/Users/jvanscho/miniconda3/lib/python3.10/site-packages/nbclient/client.py", line 965, in async_execute_cell
    await self._check_raise_for_error(cell, cell_index, exec_reply)
  File "/Users/jvanscho/miniconda3/lib/python3.10/site-packages/nbclient/client.py", line 862, in _check_raise_for_error
    raise CellExecutionError.from_cell_and_msg(cell, exec_reply_content)
nbclient.exceptions.CellExecutionError: An error occurred while executing the following cell:
------------------
# Auto-setup when running on Google Colab
if 'google.colab' in str(get_ipython()):
    !pip install openml

# General imports
%matplotlib inline
import numpy as np
import pandas as pd
import matplotlib.pyplot as plt
import openml as oml
from matplotlib import cm

# Hide convergence warning for now
import warnings
from sklearn.exceptions import ConvergenceWarning
warnings.filterwarnings("ignore", category=ConvergenceWarning)

# Hiding all warnings. Not recommended, just for compilation.
if not sys.warnoptions:
    warnings.simplefilter("ignore")
    os.environ["PYTHONWARNINGS"] = "ignore"
------------------

[0;31m---------------------------------------------------------------------------[0m
[0;31mNameError[0m                                 Traceback (most recent call last)
Cell [0;32mIn[1], line 19[0m
[1;32m     16[0m warnings[38;5;241m.[39mfilterwarnings([38;5;124m"[39m[38;5;124mignore[39m[38;5;124m"[39m, category[38;5;241m=[39mConvergenceWarning)
[1;32m     18[0m [38;5;66;03m# Hiding all warnings. Not recommended, just for compilation.[39;00m
[0;32m---> 19[0m [38;5;28;01mif[39;00m [38;5;129;01mnot[39;00m [43msys[49m[38;5;241m.[39mwarnoptions:
[1;32m     20[0m     warnings[38;5;241m.[39msimplefilter([38;5;124m"[39m[38;5;124mignore[39m[38;5;124m"[39m)
[1;32m     21[0m     os[38;5;241m.[39menviron[[38;5;124m"[39m[38;5;124mPYTHONWARNINGS[39m[38;5;124m"[39m] [38;5;241m=[39m [38;5;124m"[39m[38;5;124mignore[39m[38;5;124m"[39m

[0;31mNameError[0m: name 'sys' is not defined
NameError: name 'sys' is not defined

